<?xml version="1.0" ?>
<!-- =================================================================================== -->
<!-- |    This document was autogenerated by xacro from single_L.urdf.xacro            | -->
<!-- |    EDITING THIS FILE BY HAND IS NOT RECOMMENDED                                 | -->
<!-- =================================================================================== -->
<robot name="step_sr70_2180">
  <link name="world"/>
  <link name="base_link">
    <inertial>
      <origin rpy="0 0 0" xyz="-0.061067 0.0006943 0.14315"/>
      <mass value="68.8"/>
      <inertia ixx="1.6481" ixy="0.019568" ixz="-0.18501" iyy="2.7155" iyz="0.00082409" izz="2.9489"/>
    </inertial>
    <visual>
      <origin rpy="0 0 0" xyz="0 0 0"/>
      <geometry>
        <mesh filename="meshes/visual/base_link.STL"/>
      </geometry>
      <material name="">
        <color rgba="1 1 0 1"/>
      </material>
    </visual>
    <collision>
      <origin rpy="0 0 0" xyz="0 0 0"/>
      <geometry>
        <mesh filename="meshes/collision/base_link.STL"/>
      </geometry>
    </collision>
  </link>
  <link name="link_1">
    <inertial>
      <origin rpy="0 0 0" xyz="0.14392 0.027366 0.21033"/>
      <mass value="48.374"/>
      <inertia ixx="1.3256" ixy="0.20224" ixz="-0.2776" iyy="1.6896" iyz="-0.05764" izz="1.6484"/>
    </inertial>
    <visual>
      <origin rpy="0 0 0" xyz="0 0 0"/>
      <geometry>
        <mesh filename="meshes/visual/link_1.STL"/>
      </geometry>
      <material name="">
        <color rgba="1 1 0 1"/>
      </material>
    </visual>
    <collision>
      <origin rpy="0 0 0" xyz="0 0 0"/>
      <geometry>
        <mesh filename="meshes/collision/link_1.STL"/>
      </geometry>
    </collision>
  </link>
  <joint name="joint_1" type="revolute">
    <origin rpy="0 0 0" xyz="0 0 0.371"/>
    <parent link="base_link"/>
    <child link="link_1"/>
    <axis xyz="0 0 -1"/>
    <limit effort="0" lower="-2.7925267552" upper="2.7925267552" velocity="3.4033919829"/>
  </joint>
  <link name="link_2">
    <inertial>
      <origin rpy="0 0 0" xyz="0.0001684 -0.062639 0.26487"/>
      <mass value="12.531"/>
      <inertia ixx="1.3209" ixy="-5.1466E-05" ixz="-0.00095166" iyy="1.3647" iyz="0.051531" izz="0.08744"/>
    </inertial>
    <visual>
      <origin rpy="0 0 0" xyz="0 0 0"/>
      <geometry>
        <mesh filename="meshes/visual/link_2.STL"/>
      </geometry>
      <material name="">
        <color rgba="1 1 0 1"/>
      </material>
    </visual>
    <collision>
      <origin rpy="0 0 0" xyz="0 0 0"/>
      <geometry>
        <mesh filename="meshes/collision/link_2.STL"/>
      </geometry>
    </collision>
  </link>
  <joint name="joint_2" type="revolute">
    <origin rpy="0 0 0" xyz="0.265 -0.177 0.264"/>
    <parent link="link_1"/>
    <child link="link_2"/>
    <axis xyz="0 1 0"/>
    <limit effort="0" lower="-1.0471975331999999" upper="2.2689279886" velocity="2.9670596774"/>
  </joint>
  <link name="link_3">
    <inertial>
      <origin rpy="0 0 0" xyz="0.057293 0.19448 0.086206"/>
      <mass value="21.909"/>
      <inertia ixx="0.44896" ixy="-0.026815" ixz="-0.06957" iyy="0.40923" iyz="-0.083803" izz="0.35399"/>
    </inertial>
    <visual>
      <origin rpy="0 0 0" xyz="0 0 0"/>
      <geometry>
        <mesh filename="meshes/visual/link_3.STL"/>
      </geometry>
      <material name="">
        <color rgba="1 1 0 1"/>
      </material>
    </visual>
    <collision>
      <origin rpy="0 0 0" xyz="0 0 0"/>
      <geometry>
        <mesh filename="meshes/collision/link_3.STL"/>
      </geometry>
    </collision>
  </link>
  <joint name="joint_3" type="revolute">
    <origin rpy="0 0 0" xyz="0 -0.0359 0.85"/>
    <parent link="link_2"/>
    <child link="link_3"/>
    <axis xyz="0 1 0"/>
    <limit effort="0" lower="-3.4033919829" upper="1.3089969165" velocity="3.1066860151599998"/>
  </joint>
  <link name="link_4">
    <inertial>
      <origin rpy="0 0 0" xyz="0.47017 -0.0081466 4.8751E-05"/>
      <mass value="15.604"/>
      <inertia ixx="0.08696" ixy="0.012548" ixz="1.9054E-05" iyy="0.23365" iyz="-3.1826E-06" izz="0.27462"/>
    </inertial>
    <visual>
      <origin rpy="0 0 0" xyz="0 0 0"/>
      <geometry>
        <mesh filename="meshes/visual/link_4.STL"/>
      </geometry>
      <material name="">
        <color rgba="1 1 0 1"/>
      </material>
    </visual>
    <collision>
      <origin rpy="0 0 0" xyz="0 0 0"/>
      <geometry>
        <mesh filename="meshes/collision/link_4.STL"/>
      </geometry>
    </collision>
  </link>
  <joint name="joint_4" type="revolute">
    <origin rpy="0 0 0" xyz="0.2515 0.2189 0.16"/>
    <parent link="link_3"/>
    <child link="link_4"/>
    <axis xyz="-1 0 0"/>
    <limit effort="0" lower="-3.2288590607" upper="3.2288590607" velocity="4.5378559772"/>
  </joint>
  <link name="link_5">
    <inertial>
      <origin rpy="0 0 0" xyz="0.037812 0.091848 2.1481E-05"/>
      <mass value="6.8909"/>
      <inertia ixx="0.02976" ixy="0.0011204" ixz="3.6763E-05" iyy="0.051824" iyz="-9.4696E-06" izz="0.053443"/>
    </inertial>
    <visual>
      <origin rpy="0 0 0" xyz="0 0 0"/>
      <geometry>
        <mesh filename="meshes/visual/link_5.STL"/>
      </geometry>
      <material name="">
        <color rgba="1 1 0 1"/>
      </material>
    </visual>
    <collision>
      <origin rpy="0 0 0" xyz="0 0 0"/>
      <geometry>
        <mesh filename="meshes/collision/link_5.STL"/>
      </geometry>
    </collision>
  </link>
  <joint name="joint_5" type="revolute">
    <origin rpy="0 0 0" xyz="0.821 -0.079 0"/>
    <parent link="link_4"/>
    <child link="link_5"/>
    <axis xyz="0 1 0"/>
    <limit effort="0" lower="-2.0943950663999997" upper="2.0943950663999997" velocity="4.4505895161"/>
  </joint>
  <link name="link_6">
    <inertial>
      <origin rpy="0 0 0" xyz="-0.014796 0.00013819 0.00038893"/>
      <mass value="0.31131"/>
      <inertia ixx="0.00062907" ixy="-1.7571E-09" ixz="2.4676E-08" iyy="0.00033325" iyz="1.8187E-06" izz="0.00033482"/>
    </inertial>
    <visual>
      <origin rpy="0 0 0" xyz="0 0 0"/>
      <geometry>
        <mesh filename="meshes/visual/link_6.STL"/>
      </geometry>
      <material name="">
        <color rgba="1 1 0 1"/>
      </material>
    </visual>
    <collision>
      <origin rpy="0 0 0" xyz="0 0 0"/>
      <geometry>
        <mesh filename="meshes/collision/link_6.STL"/>
      </geometry>
    </collision>
  </link>
  <joint name="joint_6" type="revolute">
    <origin rpy="0 0 0" xyz="0.224 0.0805 0"/>
    <parent link="link_5"/>
    <child link="link_6"/>
    <axis xyz="-1 0 0"/>
    <limit effort="0" lower="-3.490658444" upper="3.490658444" velocity="6.108652277"/>
  </joint>
  <!-- ROS-Industrial 'base' frame: base_link to ABB World Coordinates transform -->
  <link name="base"/>
  <joint name="base_link-base" type="fixed">
    <origin rpy="0 0 0" xyz="0 0 0"/>
    <parent link="base_link"/>
    <child link="base"/>
  </joint>
  <!-- ROS-Industrial 'flange' frame: attachment point for EEF models -->
  <link name="flange"/>
  <joint name="joint_6-flange" type="fixed">
    <origin rpy="0 0 0" xyz="0 0 0"/>
    <parent link="link_6"/>
    <child link="flange"/>
  </joint>
  <!-- ROS-Industrial 'tool0' frame: all-zeros tool frame -->
  <link name="tool0"/>
  <joint name="link_6-tool0" type="fixed">
    <origin rpy="3.1415925996 -1.5707962998 0" xyz="0 0 0"/>
    <parent link="flange"/>
    <child link="tool0"/>
  </joint>
  <link name="sensor_link">
    <inertial>
      <origin rpy="0 0 0" xyz="9.6921E-05 0.0056052 0.22591"/>
      <mass value="26.819"/>
      <inertia ixx="0.24075" ixy="-0.00019159" ixz="-5.8354E-05" iyy="0.49843" iyz="0.0016007" izz="0.3322"/>
    </inertial>
    <visual>
      <origin rpy="0 0 0" xyz="0 0 0"/>
      <geometry>
        <mesh filename="meshes/visual/sensor_link.STL"/>
      </geometry>
      <material name="">
        <color rgba="0.75294 0.75294 0.75294 1"/>
      </material>
    </visual>
    <collision>
      <origin rpy="0 0 0" xyz="0 0 0"/>
      <geometry>
        <mesh filename="meshes/collision/sensor_link.STL"/>
      </geometry>
    </collision>
  </link>
  <joint name="sensor_joint" type="fixed">
    <origin rpy="1.5707962998 0 1.5707962998" xyz="0 0 0"/>
    <parent link="link_6"/>
    <child link="sensor_link"/>
    <axis xyz="0 0 0"/>
  </joint>
  <link name="screen_link"/>
  <joint name="screen_joint" type="fixed">
    <origin rpy="-1.5707962998 0 3.1415925996" xyz="0 -0.06687 0.2874"/>
    <parent link="sensor_link"/>
    <child link="screen_link"/>
  </joint>
  <joint name="world_base" type="fixed">
    <origin rpy="0 0 0" xyz="0 0 0"/>
    <parent link="world"/>
    <child link="base_link"/>
  </joint>
  <link name="cam2d_link"/>
  <joint name="cam2d_joint" type="fixed">
    <origin rpy="-1.92237117 -0.0156327261  1.55195991" xyz="-0.0905655582 -0.00128587879  0.448838781"/>
    <parent link="tool0"/>
    <child link="cam2d_link"/>
  </joint>
  <link name="norm_link"/>
  <joint name="norm_joint" type="fixed">
    <origin rpy="0.348584 6.25699  0.00155189" xyz="0.0000676456 0.000311004 0.224593"/>
    <parent link="cam2d_link"/>
    <child link="norm_link"/>
    <axis xyz="0 0 0"/>
  </joint>
</robot>
